<?xml version="1.0" ?>
<robot name="asimov_v1_legs">
  <link name="pelvis_link">
    <inertial>
      <origin xyz="-0.054091832 -3.4825952e-05 -0.015625518" rpy="0 0 0"/>
      <mass value="3.506912512"/>
      <inertia ixx="0.005521896904" ixy="4.558411644e-06" ixz="-7.802733884e-05" iyy="0.006266688203" iyz="1.101774672e-07" izz="0.005046553999"/>
    </inertial>
    <collision name="pelvis_collision">
      <origin xyz="-0.04 0 -0.0125" rpy="3.1415927 0 0"/>
      <geometry>
        <cylinder radius="0.04" length="0.075"/>
      </geometry>
    </collision>
    <visual name="pelvis_visual">
      <origin xyz="0 0 0" rpy="0 0 0"/>
      <geometry>
        <mesh filename="../meshes/IMU_ORIGIN.STL"/>
      </geometry>
    </visual>
  </link>
  <link name="left_hip_pitch_link">
    <inertial>
      <origin xyz="0.0017289543 0.036056326 0.00056926674" rpy="0 0 0"/>
      <mass value="1.056301122"/>
      <inertia ixx="0.0006923298908" ixy="-3.576619614e-05" ixz="1.840033682e-06" iyy="0.000812587075" iyz="1.200314764e-05" izz="0.0007533801313"/>
    </inertial>
    <collision name="left_hip_pitch_link_collision">
      <origin xyz="0 0.03 0" rpy="-1.5707963 -0 0"/>
      <geometry>
        <cylinder radius="0.04" length="0.02"/>
      </geometry>
    </collision>
    <visual name="left_hip_pitch_link_visual">
      <origin xyz="0 0 0" rpy="0 0 0"/>
      <geometry>
        <mesh filename="../meshes/LEFT_HIP_PITCH.STL"/>
      </geometry>
    </visual>
  </link>
  <joint name="left_hip_pitch_joint" type="revolute">
    <origin xyz="-0.052 0.0675 -0.044045" rpy="0 0 0"/>
    <parent link="pelvis_link"/>
    <child link="left_hip_pitch_link"/>
    <axis xyz="0 1 0"/>
    <limit lower="-2.0944" upper="1" effort="200" velocity="20"/>
  </joint>
  <link name="left_hip_roll_link">
    <inertial>
      <origin xyz="-0.011554139 -0.00033482795 -0.029410185" rpy="0 0 0"/>
      <mass value="0.4143681394"/>
      <inertia ixx="0.0002653940061" ixy="2.215143881e-06" ixz="-0.0001157810417" iyy="0.000357453871" iyz="2.984389288e-06" izz="0.0002344742715"/>
    </inertial>
    <visual name="left_hip_roll_link_visual">
      <origin xyz="0 0 0" rpy="0 0 0"/>
      <geometry>
        <mesh filename="../meshes/LEFT_HIP_ROLL.STL"/>
      </geometry>
    </visual>
  </link>
  <joint name="left_hip_roll_joint" type="revolute">
    <origin xyz="0.0422501 0.040000276 0" rpy="0 0 0"/>
    <parent link="left_hip_pitch_link"/>
    <child link="left_hip_roll_link"/>
    <axis xyz="1 0 0"/>
    <limit lower="-0.785398" upper="0.785398" effort="200" velocity="20"/>
  </joint>
  <link name="left_hip_yaw_link">
    <inertial>
      <origin xyz="0.001079482 0.0010249007 -0.12033886" rpy="0 0 0"/>
      <mass value="1.866570164"/>
      <inertia ixx="0.003416328058" ixy="1.128723441e-05" ixz="2.897790481e-05" iyy="0.003560159088" iyz="-0.0001197618954" izz="0.001375243721"/>
    </inertial>
    <collision name="left_hip_yaw_link_collision">
      <origin xyz="0 0 -0.085" rpy="3.1415927 0 0"/>
      <geometry>
        <cylinder radius="0.04" length="0.07"/>
      </geometry>
    </collision>
    <visual name="left_hip_yaw_link_visual">
      <origin xyz="0 0 0" rpy="0 0 0"/>
      <geometry>
        <mesh filename="../meshes/LEFT_HIP_YAW.STL"/>
      </geometry>
    </visual>
  </link>
  <joint name="left_hip_yaw_joint" type="revolute">
    <origin xyz="-0.04225 0 -0.052" rpy="0 0 0"/>
    <parent link="left_hip_roll_link"/>
    <child link="left_hip_yaw_link"/>
    <axis xyz="0 0 -1"/>
    <limit lower="-0.785398" upper="0.785398" effort="200" velocity="20"/>
  </joint>
  <link name="left_knee_link">
    <inertial>
      <origin xyz="-0.00050066446 0.00050928949 -0.11269289" rpy="0 0 0"/>
      <mass value="2.39114151"/>
      <inertia ixx="0.009621720602" ixy="9.876463922e-06" ixz="-0.000645140055" iyy="0.009753143566" iyz="-7.940581356e-06" izz="0.002330952369"/>
    </inertial>
    <collision name="left_knee_link_collision">
      <origin xyz="0 0 -0.13" rpy="3.1415927 0 0"/>
      <geometry>
        <cylinder radius="0.04" length="0.18"/>
      </geometry>
    </collision>
    <visual name="left_knee_link_visual">
      <origin xyz="0 0 0" rpy="0 0 0"/>
      <geometry>
        <mesh filename="../meshes/LEFT_KNEE.STL"/>
      </geometry>
    </visual>
  </link>
  <joint name="left_knee_joint" type="revolute">
    <origin xyz="0 0 -0.19564" rpy="0 0 0"/>
    <parent link="left_hip_yaw_link"/>
    <child link="left_knee_link"/>
    <axis xyz="0 1 0"/>
    <limit lower="0" upper="1.5" effort="200" velocity="20"/>
  </joint>
  <link name="left_ankle_pitch_link">
    <inertial>
      <origin xyz="-0.0011792704 -3.0701911e-08 -0.0061761924" rpy="0 0 0"/>
      <mass value="0.2730901194"/>
      <inertia ixx="6.426613198e-05" ixy="-2.405731553e-10" ixz="-1.075345119e-06" iyy="8.099442114e-05" iyz="-2.305601048e-10" izz="4.719278413e-05"/>
    </inertial>
    <visual name="left_ankle_pitch_link_visual">
      <origin xyz="0 0 0" rpy="0 0 0"/>
      <geometry>
        <mesh filename="../meshes/LEFT_ANKLE_A.STL"/>
      </geometry>
    </visual>
  </link>
  <joint name="left_ankle_pitch_joint" type="revolute">
    <origin xyz="0 0 -0.29466234" rpy="0 0 0"/>
    <parent link="left_knee_link"/>
    <child link="left_ankle_pitch_link"/>
    <axis xyz="0 1 0"/>
    <limit lower="-0.35" upper="0.35" effort="200" velocity="20"/>
  </joint>
  <link name="left_ankle_roll_link">
    <inertial>
      <origin xyz="0.042749938 0.0015925731 -0.013245066" rpy="0 0 0"/>
      <mass value="0.4056404375"/>
      <inertia ixx="0.000176487912" ixy="1.27462095e-05" ixz="-1.323273178e-05" iyy="0.0004133259112" iyz="5.53283536e-06" izz="0.000531913025"/>
    </inertial>
    <visual name="left_ankle_roll_link_visual">
      <origin xyz="0 0 0" rpy="0 0 0"/>
      <geometry>
        <mesh filename="../meshes/LEFT_ANKLE_B.STL"/>
      </geometry>
    </visual>
    <collision name="left_foot1_collision">
      <origin xyz="0.075 -0.0325 -0.022" rpy="1.5707963 1.4056476 1.4056476"/>
      <geometry>
        <cylinder radius="0.01" length="0.0304138"/>
      </geometry>
    </collision>
    <collision name="left_foot2_collision">
      <origin xyz="0.0275 -0.015 -0.022" rpy="-0 1.5707963 0"/>
      <geometry>
        <cylinder radius="0.01" length="0.125"/>
      </geometry>
    </collision>
    <collision name="left_foot3_collision">
      <origin xyz="0.0275 0 -0.022" rpy="-0 1.5707963 0"/>
      <geometry>
        <cylinder radius="0.01" length="0.125"/>
      </geometry>
    </collision>
    <collision name="left_foot4_collision">
      <origin xyz="0.0275 0.015 -0.022" rpy="-0 1.5707963 0"/>
      <geometry>
        <cylinder radius="0.01" length="0.125"/>
      </geometry>
    </collision>
    <collision name="left_foot6_collision">
      <origin xyz="0.045 0.0325 -0.022" rpy="-1.5707963 1.5152978 -1.5152978"/>
      <geometry>
        <cylinder radius="0.01" length="0.0901388"/>
      </geometry>
    </collision>
  </link>
  <joint name="left_ankle_roll_joint" type="revolute">
    <origin xyz="-0.0015 0 -0.009999992" rpy="0 0 0"/>
    <parent link="left_ankle_pitch_link"/>
    <child link="left_ankle_roll_link"/>
    <axis xyz="-1 0 0"/>
    <limit lower="-0.1" upper="0.1" effort="200" velocity="20"/>
  </joint>
  <link name="left_toe_link">
    <inertial>
      <origin xyz="0.032016777 0.00071824851 -0.014131277" rpy="0 0 0"/>
      <mass value="0.1122212379"/>
      <inertia ixx="5.535192522e-05" ixy="0" ixz="0" iyy="3.651308095e-05" iyz="0" izz="8.540299695e-05"/>
    </inertial>
    <visual name="left_toe_link_visual">
      <origin xyz="0 0.008 0" rpy="0 0 0"/>
      <geometry>
        <mesh filename="../meshes/LEFT_TOE.STL"/>
      </geometry>
    </visual>
    <collision name="left_toe1_collision">
      <origin xyz="0.025 -0.03 -0.018" rpy="-0 1.5707963 0"/>
      <geometry>
        <cylinder radius="0.01" length="0.03"/>
      </geometry>
    </collision>
    <collision name="left_toe2_collision">
      <origin xyz="0.0325 -0.015 -0.018" rpy="-0 1.5707963 0"/>
      <geometry>
        <cylinder radius="0.01" length="0.045"/>
      </geometry>
    </collision>
    <collision name="left_toe3_collision">
      <origin xyz="0.035 0 -0.018" rpy="-0 1.5707963 0"/>
      <geometry>
        <cylinder radius="0.01" length="0.05"/>
      </geometry>
    </collision>
    <collision name="left_toe4_collision">
      <origin xyz="0.0325 0.02 -0.018" rpy="-0 1.5707963 0"/>
      <geometry>
        <cylinder radius="0.01" length="0.045"/>
      </geometry>
    </collision>
    <collision name="left_toe5_collision">
      <origin xyz="0.025 0.04 -0.018" rpy="-0 1.5707963 0"/>
      <geometry>
        <cylinder radius="0.01" length="0.03"/>
      </geometry>
    </collision>
  </link>
  <joint name="left_toe_joint" type="fixed">
    <origin xyz="0.10253 -0.0043664 -0.0067324" rpy="0 0 0"/>
    <parent link="left_ankle_roll_link"/>
    <child link="left_toe_link"/>
  </joint>
  <link name="right_hip_pitch_link">
    <inertial>
      <origin xyz="0.0017289154 -0.036056078 0.00056883085" rpy="0 0 0"/>
      <mass value="1.056297429"/>
      <inertia ixx="0.0006923291362" ixy="3.576503727e-05" ixz="1.840998202e-06" iyy="0.0008125825587" iyz="-1.200753871e-05" izz="0.0007533841087"/>
    </inertial>
    <collision name="right_hip_pitch_link_collision">
      <origin xyz="0 -0.03 0" rpy="1.5707963 -0 0"/>
      <geometry>
        <cylinder radius="0.04" length="0.02"/>
      </geometry>
    </collision>
    <visual name="right_hip_pitch_link_visual">
      <origin xyz="0 0 0" rpy="0 0 0"/>
      <geometry>
        <mesh filename="../meshes/RIGHT_HIP_PITCH.STL"/>
      </geometry>
    </visual>
  </link>
  <joint name="right_hip_pitch_joint" type="revolute">
    <origin xyz="-0.052 -0.0675 -0.044045" rpy="0 0 0"/>
    <parent link="pelvis_link"/>
    <child link="right_hip_pitch_link"/>
    <axis xyz="0 -1 0"/>
    <limit lower="-1" upper="2.0944" effort="200" velocity="20"/>
  </joint>
  <link name="right_hip_roll_link">
    <inertial>
      <origin xyz="-0.011543567 0.00036145871 -0.029385891" rpy="0 0 0"/>
      <mass value="0.4148250006"/>
      <inertia ixx="0.0002658932272" ixy="-2.331358933e-06" ixz="-0.0001158839661" iyy="0.0003577347501" iyz="-3.2326209e-06" izz="0.0002348039242"/>
    </inertial>
    <visual name="right_hip_roll_link_visual">
      <origin xyz="0 0 0" rpy="0 0 0"/>
      <geometry>
        <mesh filename="../meshes/RIGHT_HIP_ROLL.STL"/>
      </geometry>
    </visual>
  </link>
  <joint name="right_hip_roll_joint" type="revolute">
    <origin xyz="0.04225 -0.04 0" rpy="0 0 0"/>
    <parent link="right_hip_pitch_link"/>
    <child link="right_hip_roll_link"/>
    <axis xyz="1 0 0"/>
    <limit lower="-0.785398" upper="0.785398" effort="200" velocity="20"/>
  </joint>
  <link name="right_hip_yaw_link">
    <inertial>
      <origin xyz="0.0010759525 -0.001021765 -0.12034512" rpy="0 0 0"/>
      <mass value="1.866472204"/>
      <inertia ixx="0.003415887345" ixy="-1.175977833e-05" ixz="2.917335953e-05" iyy="0.003559900155" iyz="0.0001197156713" izz="0.001375252722"/>
    </inertial>
    <collision name="right_hip_yaw_link_collision">
      <origin xyz="0 0 -0.085" rpy="3.1415927 0 0"/>
      <geometry>
        <cylinder radius="0.04" length="0.07"/>
      </geometry>
    </collision>
    <visual name="right_hip_yaw_link_visual">
      <origin xyz="0 0 0" rpy="0 0 0"/>
      <geometry>
        <mesh filename="../meshes/RIGHT_HIP_YAW.STL"/>
      </geometry>
    </visual>
  </link>
  <joint name="right_hip_yaw_joint" type="revolute">
    <origin xyz="-0.04225 0 -0.052" rpy="0 0 0"/>
    <parent link="right_hip_roll_link"/>
    <child link="right_hip_yaw_link"/>
    <axis xyz="0 0 -1"/>
    <limit lower="-0.785398" upper="0.785398" effort="200" velocity="20"/>
  </joint>
  <link name="right_knee_link">
    <inertial>
      <origin xyz="-0.00049758723 -0.00041475722 -0.11269269" rpy="0 0 0"/>
      <mass value="2.391101727"/>
      <inertia ixx="0.009621482138" ixy="-9.875278239e-06" ixz="-0.0006450947183" iyy="0.00975287238" iyz="7.984313674e-06" izz="0.002330903583"/>
    </inertial>
    <collision name="right_knee_link_collision">
      <origin xyz="0 0 -0.13" rpy="3.1415927 0 0"/>
      <geometry>
        <cylinder radius="0.04" length="0.18"/>
      </geometry>
    </collision>
    <visual name="right_knee_link_visual">
      <origin xyz="0 0 0" rpy="0 0 0"/>
      <geometry>
        <mesh filename="../meshes/RIGHT_KNEE.STL"/>
      </geometry>
    </visual>
  </link>
  <joint name="right_knee_joint" type="revolute">
    <origin xyz="0 0 -0.19564" rpy="0 0 0"/>
    <parent link="right_hip_yaw_link"/>
    <child link="right_knee_link"/>
    <axis xyz="0 -1 0"/>
    <limit lower="-1.5" upper="0" effort="200" velocity="20"/>
  </joint>
  <link name="right_ankle_pitch_link">
    <inertial>
      <origin xyz="-0.0011793693 6.8671686e-08 -0.0061761458" rpy="0 0 0"/>
      <mass value="0.2730891716"/>
      <inertia ixx="6.426594521e-05" ixy="-1.022813458e-10" ixz="-1.075587701e-06" iyy="8.099443484e-05" iyz="3.527011844e-10" izz="4.719260128e-05"/>
    </inertial>
    <visual name="right_ankle_pitch_link_visual">
      <origin xyz="0 0 0" rpy="0 0 0"/>
      <geometry>
        <mesh filename="../meshes/RIGHT_ANKLE_A.STL"/>
      </geometry>
    </visual>
  </link>
  <joint name="right_ankle_pitch_joint" type="revolute">
    <origin xyz="0 0.0001 -0.29466234" rpy="0 0 0"/>
    <parent link="right_knee_link"/>
    <child link="right_ankle_pitch_link"/>
    <axis xyz="0 -1 0"/>
    <limit lower="-0.35" upper="0.35" effort="200" velocity="20"/>
  </joint>
  <link name="right_ankle_roll_link">
    <inertial>
      <origin xyz="0.037604624 -0.0011327012 -0.012066752" rpy="0 0 0"/>
      <mass value="0.4056404375"/>
      <inertia ixx="0.0001864220342" ixy="-1.268263551e-05" ixz="-1.313471744e-05" iyy="0.0004161542882" iyz="-5.519847575e-06" izz="0.0005383165152"/>
    </inertial>
    <visual name="right_ankle_roll_link_visual">
      <origin xyz="0 0 0" rpy="0 0 0"/>
      <geometry>
        <mesh filename="../meshes/RIGHT_ANKLE_B.STL"/>
      </geometry>
    </visual>
    <collision name="right_foot1_collision">
      <origin xyz="0.045 -0.0325 -0.022" rpy="1.5707963 1.5152978 1.5152978"/>
      <geometry>
        <cylinder radius="0.01" length="0.0901388"/>
      </geometry>
    </collision>
    <collision name="right_foot2_collision">
      <origin xyz="0.0275 -0.015 -0.022" rpy="-0 1.5707963 0"/>
      <geometry>
        <cylinder radius="0.01" length="0.125"/>
      </geometry>
    </collision>
    <collision name="right_foot3_collision">
      <origin xyz="0.0275 0 -0.022" rpy="-0 1.5707963 0"/>
      <geometry>
        <cylinder radius="0.01" length="0.125"/>
      </geometry>
    </collision>
    <collision name="right_foot4_collision">
      <origin xyz="0.0275 0.015 -0.022" rpy="-0 1.5707963 0"/>
      <geometry>
        <cylinder radius="0.01" length="0.125"/>
      </geometry>
    </collision>
    <collision name="right_foot5_collision">
      <origin xyz="0.075 0.0325 -0.022" rpy="-1.5707963 1.4056476 -1.4056476"/>
      <geometry>
        <cylinder radius="0.01" length="0.0304138"/>
      </geometry>
    </collision>
  </link>
  <joint name="right_ankle_roll_joint" type="revolute">
    <origin xyz="-0.0015 0 -0.009999992" rpy="0 0 0"/>
    <parent link="right_ankle_pitch_link"/>
    <child link="right_ankle_roll_link"/>
    <axis xyz="-1 0 0"/>
    <limit lower="-0.1" upper="0.1" effort="200" velocity="20"/>
  </joint>
  <link name="right_toe_link">
    <inertial>
      <origin xyz="0.032014175 -0.00081670801 -0.014130909" rpy="0 0 0"/>
      <mass value="0.1122217541"/>
      <inertia ixx="5.53589487e-05" ixy="0" ixz="0" iyy="3.6505277e-05" iyz="0" izz="8.540173571e-05"/>
    </inertial>
    <visual name="right_toe_link_visual">
      <origin xyz="0 -0.008 0" rpy="0 0 0"/>
      <geometry>
        <mesh filename="../meshes/RIGHT_TOE.STL"/>
      </geometry>
    </visual>
    <collision name="right_toe1_collision">
      <origin xyz="0.025 -0.04 -0.018" rpy="-0 1.5707963 0"/>
      <geometry>
        <cylinder radius="0.01" length="0.03"/>
      </geometry>
    </collision>
    <collision name="right_toe2_collision">
      <origin xyz="0.0325 -0.02 -0.018" rpy="-0 1.5707963 0"/>
      <geometry>
        <cylinder radius="0.01" length="0.045"/>
      </geometry>
    </collision>
    <collision name="right_toe3_collision">
      <origin xyz="0.035 0 -0.018" rpy="-0 1.5707963 0"/>
      <geometry>
        <cylinder radius="0.01" length="0.05"/>
      </geometry>
    </collision>
    <collision name="right_toe4_collision">
      <origin xyz="0.0325 0.015 -0.018" rpy="-0 1.5707963 0"/>
      <geometry>
        <cylinder radius="0.01" length="0.045"/>
      </geometry>
    </collision>
    <collision name="right_toe5_collision">
      <origin xyz="0.025 0.03 -0.018" rpy="-0 1.5707963 0"/>
      <geometry>
        <cylinder radius="0.01" length="0.03"/>
      </geometry>
    </collision>
  </link>
  <joint name="right_toe_joint" type="fixed">
    <origin xyz="0.10247 0.0042796 -0.0067324" rpy="0 0 0"/>
    <parent link="right_ankle_roll_link"/>
    <child link="right_toe_link"/>
  </joint>
  <link name="waist_yaw_link">
    <inertial>
      <origin xyz="-0.0069939364 -2.5081213e-05 0.20403988" rpy="0 0 0"/>
      <mass value="8.208501581"/>
      <inertia ixx="0.04981397107" ixy="-2.411153088e-05" ixz="0.003192305044" iyy="0.0397024418" iyz="-1.460929099e-05" izz="0.03212665803"/>
    </inertial>
    <collision name="waist_yaw_link_collision">
      <origin xyz="0 0 0.175" rpy="0 -0 0"/>
      <geometry>
        <cylinder radius="0.06" length="0.25"/>
      </geometry>
    </collision>
    <visual name="waist_yaw_link_visual">
      <origin xyz="0 0 0" rpy="0 0 0"/>
      <geometry>
        <mesh filename="../meshes/WAIST_YAW.STL"/>
      </geometry>
    </visual>
  </link>
  <joint name="waist_yaw_joint" type="fixed">
    <origin xyz="-0.052 0 0.074755" rpy="0 0 0"/>
    <parent link="pelvis_link"/>
    <child link="waist_yaw_link"/>
  </joint>
  <link name="neck_yaw_link">
    <inertial>
      <origin xyz="-0.00023215505 -0.00068693239 0.035674684" rpy="0 0 0"/>
      <mass value="0.5327893053"/>
      <inertia ixx="0.000264347243" ixy="-3.484135137e-12" ixz="1.212626814e-05" iyy="0.0002487715643" iyz="-8.873647228e-11" izz="0.0002019309198"/>
    </inertial>
    <visual name="neck_yaw_link_visual">
      <origin xyz="0 0 0" rpy="0 0 0"/>
      <geometry>
        <mesh filename="../meshes/NECK_YAW.STL"/>
      </geometry>
    </visual>
  </link>
  <joint name="neck_yaw_joint" type="fixed">
    <origin xyz="-0.016598775 0 0.37816703" rpy="0 0 0"/>
    <parent link="waist_yaw_link"/>
    <child link="neck_yaw_link"/>
  </joint>
  <link name="neck_pitch_link">
    <inertial>
      <origin xyz="0.012388775 0.00086195212 0.042518927" rpy="0 0 0"/>
      <mass value="0.3940556092"/>
      <inertia ixx="0.001287267119" ixy="3.551753115e-07" ixz="0.0001425546374" iyy="0.001730870704" iyz="-3.997831799e-07" izz="0.00145145415"/>
    </inertial>
    <collision name="neck_pitch_link_collision">
      <origin xyz="0.03 0 0.02" rpy="0 -0 0"/>
      <geometry>
        <cylinder radius="0.05" length="0.04"/>
      </geometry>
    </collision>
    <visual name="neck_pitch_link_visual">
      <origin xyz="0 0 0" rpy="0 0 0"/>
      <geometry>
        <mesh filename="../meshes/NECK_PITCH.STL"/>
      </geometry>
    </visual>
  </link>
  <joint name="neck_pitch_joint" type="fixed">
    <origin xyz="0 0 0.03735" rpy="0 0 0"/>
    <parent link="neck_yaw_link"/>
    <child link="neck_pitch_link"/>
  </joint>
  <link name="right_shoulder_pitch_link">
    <inertial>
      <origin xyz="0.00012981097 -0.015792183 -1.8861692e-05" rpy="0 0 0"/>
      <mass value="0.5991561057"/>
      <inertia ixx="0.0003303181508" ixy="-2.568852685e-07" ixz="2.440637577e-09" iyy="0.0004185132624" iyz="-3.986644146e-10" izz="0.0004213841436"/>
    </inertial>
    <visual name="right_shoulder_pitch_link_visual">
      <origin xyz="0 0 0" rpy="0 0 0"/>
      <geometry>
        <mesh filename="../meshes/RIGHT_SHOULDER_PITCH.STL"/>
      </geometry>
    </visual>
  </link>
  <joint name="right_shoulder_pitch_joint" type="fixed">
    <origin xyz="-0.026212825 -0.0965 0.26114048" rpy="0 0 0"/>
    <parent link="waist_yaw_link"/>
    <child link="right_shoulder_pitch_link"/>
  </joint>
  <link name="right_shoulder_roll_link">
    <inertial>
      <origin xyz="0.00011417762 -4.3514215e-05 -0.037310069" rpy="0 0 0"/>
      <mass value="1.313222376"/>
      <inertia ixx="0.001632804646" ixy="4.422950386e-07" ixz="9.017972571e-07" iyy="0.001491484773" iyz="3.090767038e-06" izz="0.0007407853478"/>
    </inertial>
    <collision name="right_shoulder_roll_link_collision">
      <origin xyz="0 -0.01 -0.065" rpy="3.1415927 0 0"/>
      <geometry>
        <cylinder radius="0.035" length="0.09"/>
      </geometry>
    </collision>
    <visual name="right_shoulder_roll_link_visual">
      <origin xyz="0 0 0" rpy="0 0 0"/>
      <geometry>
        <mesh filename="../meshes/RIGHT_SHOULDER_ROLL.STL"/>
      </geometry>
    </visual>
  </link>
  <joint name="right_shoulder_roll_joint" type="fixed">
    <origin xyz="0 -0.065353223 -6.334135e-05" rpy="0 0 0"/>
    <parent link="right_shoulder_pitch_link"/>
    <child link="right_shoulder_roll_link"/>
  </joint>
  <link name="right_shoulder_yaw_link">
    <inertial>
      <origin xyz="-0.00032506612 0.00032050396 -0.075940499" rpy="0 0 0"/>
      <mass value="0.7122617553"/>
      <inertia ixx="0.0005026643424" ixy="1.038748269e-07" ixz="3.848986797e-07" iyy="0.0005162594955" iyz="-9.284062409e-07" izz="0.0003106780038"/>
    </inertial>
    <visual name="right_shoulder_yaw_link_visual">
      <origin xyz="0 0 0" rpy="0 0 0"/>
      <geometry>
        <mesh filename="../meshes/RIGHT_SHOULDER_YAW.STL"/>
      </geometry>
    </visual>
  </link>
  <joint name="right_shoulder_yaw_joint" type="fixed">
    <origin xyz="0 0 -0.12899875" rpy="0 0 0"/>
    <parent link="right_shoulder_roll_link"/>
    <child link="right_shoulder_yaw_link"/>
  </joint>
  <link name="right_elbow_link">
    <inertial>
      <origin xyz="0.052375599 -9.8430423e-05 -0.044442591" rpy="0 0 0"/>
      <mass value="0.6623142589"/>
      <inertia ixx="0.0003317099774" ixy="1.143787702e-07" ixz="5.587067574e-05" iyy="0.0004184328786" iyz="-9.740426844e-08" izz="0.0003678169223"/>
    </inertial>
    <collision name="right_elbow_link_collision">
      <origin xyz="0.045 -0.01 -0.035" rpy="3.1415927 0.90975316 3.1415927"/>
      <geometry>
        <cylinder radius="0.03" length="0.114018"/>
      </geometry>
    </collision>
    <visual name="right_elbow_link_visual">
      <origin xyz="0 0 0" rpy="0 0 0"/>
      <geometry>
        <mesh filename="../meshes/RIGHT_ELBOW.STL"/>
      </geometry>
    </visual>
  </link>
  <joint name="right_elbow_joint" type="fixed">
    <origin xyz="0 0 -0.0966013" rpy="0 0 0"/>
    <parent link="right_shoulder_yaw_link"/>
    <child link="right_elbow_link"/>
  </joint>
  <link name="right_wrist_yaw_link">
    <inertial>
      <origin xyz="0.0038228913 8.3654031e-09 -0.0032077859" rpy="0 0 0"/>
      <mass value="0.05805951068"/>
      <inertia ixx="1.188030017e-05" ixy="3.737968677e-08" ixz="-3.063460189e-06" iyy="8.854608036e-06" iyz="4.454234307e-08" izz="1.079993917e-05"/>
    </inertial>
    <visual name="right_wrist_yaw_link_visual">
      <origin xyz="0 0 0" rpy="0 0 0"/>
      <geometry>
        <mesh filename="../meshes/RIGHT_WRIST_YAW.STL"/>
      </geometry>
    </visual>
  </link>
  <joint name="right_wrist_yaw_joint" type="fixed">
    <origin xyz="0.086563022 0 -0.072635" rpy="0 0 0"/>
    <parent link="right_elbow_link"/>
    <child link="right_wrist_yaw_link"/>
  </joint>
  <link name="left_shoulder_pitch_link">
    <inertial>
      <origin xyz="0.00015988948 0.015791587 -3.4820319e-07" rpy="0 0 0"/>
      <mass value="0.5991571366"/>
      <inertia ixx="0.0003303159213" ixy="2.455356997e-07" ixz="-2.283631785e-09" iyy="0.0004185178584" iyz="-1.018548534e-08" izz="0.0004213791655"/>
    </inertial>
    <visual name="left_shoulder_pitch_link_visual">
      <origin xyz="0 0 0" rpy="0 0 0"/>
      <geometry>
        <mesh filename="../meshes/LEFT_SHOULDER_PITCH.STL"/>
      </geometry>
    </visual>
  </link>
  <joint name="left_shoulder_pitch_joint" type="fixed">
    <origin xyz="-0.026212825 0.0965 0.26114048" rpy="0 0 0"/>
    <parent link="waist_yaw_link"/>
    <child link="left_shoulder_pitch_link"/>
  </joint>
  <link name="left_shoulder_roll_link">
    <inertial>
      <origin xyz="0.00011401839 4.3288067e-05 -0.03731006" rpy="0 0 0"/>
      <mass value="1.31322813"/>
      <inertia ixx="0.001632813644" ixy="-4.363223112e-07" ixz="9.066462214e-07" iyy="0.001491474896" iyz="-3.084593145e-06" izz="0.0007408097904"/>
    </inertial>
    <collision name="left_shoulder_roll_link_collision">
      <origin xyz="0 0.01 -0.065" rpy="3.1415927 0 0"/>
      <geometry>
        <cylinder radius="0.035" length="0.09"/>
      </geometry>
    </collision>
    <visual name="left_shoulder_roll_link_visual">
      <origin xyz="0 0 0" rpy="0 0 0"/>
      <geometry>
        <mesh filename="../meshes/LEFT_SHOULDER_ROLL.STL"/>
      </geometry>
    </visual>
  </link>
  <joint name="left_shoulder_roll_joint" type="fixed">
    <origin xyz="0.0001 0.065353223 0" rpy="0 0 0"/>
    <parent link="left_shoulder_pitch_link"/>
    <child link="left_shoulder_roll_link"/>
  </joint>
  <link name="left_shoulder_yaw_link">
    <inertial>
      <origin xyz="-0.00033000064 0.00013603672 -0.07536191" rpy="0 0 0"/>
      <mass value="0.7122617553"/>
      <inertia ixx="0.0005013958201" ixy="-1.035724302e-07" ixz="3.857240017e-07" iyy="0.0005146327974" iyz="9.789699759e-07" izz="0.000310276967"/>
    </inertial>
    <visual name="left_shoulder_yaw_link_visual">
      <origin xyz="0 0 0" rpy="0 0 0"/>
      <geometry>
        <mesh filename="../meshes/LEFT_SHOULDER_YAW.STL"/>
      </geometry>
    </visual>
  </link>
  <joint name="left_shoulder_yaw_joint" type="fixed">
    <origin xyz="0 0 -0.12899875" rpy="0 0 0"/>
    <parent link="left_shoulder_roll_link"/>
    <child link="left_shoulder_yaw_link"/>
  </joint>
  <link name="left_elbow_link">
    <inertial>
      <origin xyz="0.052375642 9.8472335e-05 -0.044442643" rpy="0 0 0"/>
      <mass value="0.6623176013"/>
      <inertia ixx="0.0003317095185" ixy="-1.152654524e-07" ixz="5.587342465e-05" iyy="0.0004184302982" iyz="9.677953854e-08" izz="0.0003678178442"/>
    </inertial>
    <collision name="left_elbow_link_collision">
      <origin xyz="0.045 0.01 -0.035" rpy="3.1415927 0.90975316 3.1415927"/>
      <geometry>
        <cylinder radius="0.03" length="0.114018"/>
      </geometry>
    </collision>
    <visual name="left_elbow_link_visual">
      <origin xyz="0 0 0" rpy="0 0 0"/>
      <geometry>
        <mesh filename="../meshes/LEFT_ELBOW.STL"/>
      </geometry>
    </visual>
  </link>
  <joint name="left_elbow_joint" type="fixed">
    <origin xyz="0 0 -0.0963013" rpy="0 0 0"/>
    <parent link="left_shoulder_yaw_link"/>
    <child link="left_elbow_link"/>
  </joint>
  <link name="left_wrist_yaw_link">
    <inertial>
      <origin xyz="0.0038228932 1.7394453e-08 -0.003207742" rpy="0 0 0"/>
      <mass value="0.05805879065"/>
      <inertia ixx="1.20674298e-05" ixy="1.833353459e-07" ixz="-2.840253656e-06" iyy="8.401301399e-06" iyz="2.184793015e-07" izz="1.106580349e-05"/>
    </inertial>
    <visual name="left_wrist_yaw_link_visual">
      <origin xyz="0 0 0" rpy="0 0 0"/>
      <geometry>
        <mesh filename="../meshes/LEFT_WRIST_YAW.STL"/>
      </geometry>
    </visual>
  </link>
  <joint name="left_wrist_yaw_joint" type="fixed">
    <origin xyz="0.086563022 0 -0.072635" rpy="0 0 0"/>
    <parent link="left_elbow_link"/>
    <child link="left_wrist_yaw_link"/>
  </joint>
</robot>
